Workbook

Sheet working data
A1: Order ID | B1: Date | C1: Region | D1: Product | E1: Category | F1: Quantity | G1: Unit Price | H1: Total sales | I1: month
A2: 1001 | B2: 45658 | C2: North | D2: Notebook Pack | E2: Stationery | F2: 7 | G2: 250 | H2: =F2*G2 -> 1750 | I2: =TEXT(B2,"mmm") -> Jan
A3: 1002 | B3: 45658 | C3: West | D3: Mobile | E3: Electronics | F3: 2 | G3: 18000 | H3: =F3*G3 -> 36000 | I3: =TEXT(B3,"mmm") -> Jan
A4: 1003 | B4: 45658 | C4: North | D4: Headphones | E4: Electronics | F4: 4 | G4: 2000 | H4: =F4*G4 -> 8000 | I4: =TEXT(B4,"mmm") -> Jan
A5: 1004 | B5: 45659 | C5: East | D5: Study Table | E5: Furniture | F5: 6 | G5: 5200 | H5: =F5*G5 -> 31200 | I5: =TEXT(B5,"mmm") -> Jan
A6: 1005 | B6: 45659 | C6: North | D6: Backpack | E6: Accessories | F6: 2 | G6: 1500 | H6: =F6*G6 -> 3000 | I6: =TEXT(B6,"mmm") -> Jan
A7: 1006 | B7: 45660 | C7: East | D7: Headphones | E7: Electronics | F7: 7 | G7: 2000 | H7: =F7*G7 -> 14000 | I7: =TEXT(B7,"mmm") -> Jan
A8: 1007 | B8: 45663 | C8: West | D8: Notebook Pack | E8: Stationery | F8: 9 | G8: 250 | H8: =F8*G8 -> 2250 | I8: =TEXT(B8,"mmm") -> Jan
A9: 1008 | B9: 45664 | C9: West | D9: Backpack | E9: Accessories | F9: 1 | G9: 1500 | H9: =F9*G9 -> 1500 | I9: =TEXT(B9,"mmm") -> Jan
A10: 1009 | B10: 45667 | C10: West | D10: Notebook Pack | E10: Stationery | F10: 9 | G10: 250 | H10: =F10*G10 -> 2250 | I10: =TEXT(B10,"mmm") -> Jan
A11: 1010 | B11: 45667 | C11: North | D11: Study Table | E11: Furniture | F11: 1 | G11: 5200 | H11: =F11*G11 -> 5200 | I11: =TEXT(B11,"mmm") -> Jan
A12: 1011 | B12: 45667 | C12: West | D12: Office Chair | E12: Furniture | F12: 9 | G12: 6500 | H12: =F12*G12 -> 58500 | I12: =TEXT(B12,"mmm") -> Jan
A13: 1012 | B13: 45668 | C13: North | D13: Laptop | E13: Electronics | F13: 3 | G13: 45000 | H13: =F13*G13 -> 135000 | I13: =TEXT(B13,"mmm") -> Jan
... A200: 1200 | B200: 46016 | C200: North | D200: Backpack | E200: Accessories | F200: 2 | G200: 1500 | H200: =F200*G200 -> 3000 | I200: =TEXT(B200,"mmm") -> Dec

Sheet summary
A1: key number | B1: total sales | C1: number of orders | D1: average order value | E1: biggest sale | F1: smallest sales
B2: =SUM('working data'!H:H) -> 5019390 | C2: =COUNT('working data'!A:A) -> 199 | D2: =B2/C2 -> 25223.065 | E2: =MAX('working data'!H:H) -> 135000 | F2: =MIN('working data'!H:H) -> 120
A5: REGION | B5: TOTAL SALES
A6: north | B6: =SUMIF('working data'!C:C,A6,'working data'!H:H) -> 1362280
A7: south | B7: =SUMIF('working data'!C:C,A7,'working data'!H:H) -> 1247230
A8: east | B8: =SUMIF('working data'!C:C,A8,'working data'!H:H) -> 1009770
A9: west | B9: =SUMIF('working data'!C:C,A9,'working data'!H:H) -> 1355110
A10: unknown | B10: =SUMIF('working data'!C:C,A10,'working data'!H:H) -> 45000
A11: TOTAL | B11: =SUM(B6:B10) -> 5019390
A14: PRODUCT | B14: TOTAL SALES
A15: Laptop | B15: =SUMIF('working data'!D:D,A15,'working data'!H:H) -> 2160000
A16: mobile | B16: =SUMIF('working data'!D:D,A16,'working data'!H:H) -> 684000
A17: Headphones | B17: =SUMIF('working data'!D:D,A17,'working data'!H:H) -> 294000
A18: Office Chair | B18: =SUMIF('working data'!D:D,A18,'working data'!H:H) -> 806000
A19: Study Table | B19: =SUMIF('working data'!D:D,A19,'working data'!H:H) -> 774800
A20: Notebook Pack | B20: =SUMIF('working data'!D:D,A20,'working data'!H:H) -> 31250
A21: pen box | B21: =SUMIF('working data'!D:D,A21,'working data'!H:H) -> 12840
A22: backpack | B22: =SUMIF('working data'!D:D,A22,'working data'!H:H) -> 256500
A23: TOTAL | B23: =SUM(B15:B22) -> 5019390
A26: MONTH | B26: TOTAL SALES
A27: jan | B27: =SUMIF('working data'!I:I,A27,'working data'!H:H) -> 453390
A28: feb | B28: =SUMIF('working data'!I:I,A28,'working data'!H:H) -> 447670
A29: mar | B29: =SUMIF('working data'!I:I,A29,'working data'!H:H) -> 231500
A30: apr | B30: =SUMIF('working data'!I:I,A30,'working data'!H:H) -> 529900
A31: may | B31: =SUMIF('working data'!I:I,A31,'working data'!H:H) -> 606220
A32: jun | B32: =SUMIF('working data'!I:I,A32,'working data'!H:H) -> 298730
A33: jul | B33: =SUMIF('working data'!I:I,A33,'working data'!H:H) -> 448180
A34: aug | B34: =SUMIF('working data'!I:I,A34,'working data'!H:H) -> 513270
A35: sep | B35: =SUMIF('working data'!I:I,A35,'working data'!H:H) -> 641190
A36: oct | B36: =SUMIF('working data'!I:I,A36,'working data'!H:H) -> 346200
A37: nov | B37: =SUMIF('working data'!I:I,A37,'working data'!H:H) -> 258940
A38: dec | B38: =SUMIF('working data'!I:I,A38,'working data'!H:H) -> 244200
A39: TOTAL | B39: =SUM(B27:B38) -> 5019390

Sheet DASHBORD
B1: SALES DASHBOARD 2025
B3: TOTAL SALES | D3: TOTAL ORDERS | F3: AVG ORDER VALUE | H3: BIGGEST SALES
B4: =summary!B2 -> 5019390 | D4: =summary!C2 -> 199 | F4: =ROUND(summary!D2,0) -> 25223 | H4: =summary!E2 -> 135000

Sheet insights
A1: KEY INSIGHTS
A3: Laptops bring in 43% of total sales (2,160,000), making them the top product by far
A4: North is the best region (27% of sales), but West is almost equal, and East is the lowest main region at 20%
A5: September is the best month (641,190) and March is the weakest (231,500).
A6: Sales dropped towards the end of the year, from October to December.
A7: One order has an unknown region, so region records should be filled in more carefully.
A9: Recommendation: Run a sales campaign in East and in the weak months (March, November and December)

Sheet Sales Data
A1: Order ID | B1: Date | C1: Region | D1: Product | E1: Category | F1: Quantity | G1: Unit Price
A2: 1001 | B2: 45658 | C2: North | D2: Notebook Pack | E2: Stationery | F2: 7 | G2: 250
A3: 1002 | B3: 45658 | C3: West | D3: Mobile | E3: Electronics | F3: 2 | G3: 18000
A4: 1003 | B4: 45658 | C4: North | D4: Headphones | E4: Electronics | F4: 4 | G4: 2000
A5: 1004 | B5: 45659 | C5: East | D5: Study Table | E5: Furniture | F5: 6 | G5: 5200
A6: 1005 | B6: 45659 | C6: North | D6: Backpack | E6: Accessories | F6: 2 | G6: 1500
A7: 1006 | B7: 45660 | C7: East | D7: Headphones | E7: Electronics | F7: 7 | G7: 2000
A8: 1007 | B8: 45663 | C8: West | D8: Notebook Pack | E8: Stationery | F8: 9 | G8: 250
A9: 1008 | B9: 45664 | C9: West | D9: Backpack | E9: Accessories | F9: 1 | G9: 1500
A10: 1009 | B10: 45667 | C10: West | D10: Notebook Pack | E10: Stationery | F10: 9 | G10: 250
A11: 1010 | B11: 45667 | C11: North | D11: Study Table | E11: Furniture | F11: 1 | G11: 5200
A12: 1011 | B12: 45667 | C12: West | D12: Office Chair | E12: Furniture | F12: 9 | G12: 6500
A13: 1012 | B13: 45668 | C13: North | D13: Laptop | E13: Electronics | F13: 3 | G13: 45000
... A31: 1030 | B31: 45700 | C31: South | D31: Headphones | E31: Electronics | F31: 3 | G31: 2000
A32: 1031 | B32: 45701 | D32: Laptop | E32: Electronics | F32: 1 | G32: 45000
A33: 1032 | B33: 45703 | C33: North | D33: Headphones | E33: Electronics | F33: 7 | G33: 2000
A34: 1033 | B34: 45704 | C34: North | D34: Pen Box | E34: Stationery | F34: 1 | G34: 120
A35: 1034 | B35: 45710 | C35: North | D35: Office Chair | E35: Furniture | F35: 6 | G35: 6500
A36: 1035 | B36: 45710 | C36: West | D36: Notebook Pack | E36: Stationery | F36: 5 | G36: 250
A37: 1036 | B37: 45712 | C37: South | D37: Laptop | E37: Electronics | F37: 1 | G37: 45000
A38: 1037 | B38: 45714 | C38: North | D38: Headphones | E38: Electronics | F38: 5 | G38: 2000
A39: 1038 | B39: 45715 | C39: North | D39: Office Chair | E39: Furniture | F39: 2 | G39: 6500
A40: 1039 | B40: 45717 | C40: West | D40: Backpack | E40: Accessories | F40: 8 | G40: 1500
A41: 1040 | B41: 45719 | C41: North | D41: Headphones | E41: Electronics | F41: 3 | G41: 2000
A42: 1041 | B42: 45722 | C42: East | D42: Office Chair | E42: Furniture | F42: 2 | G42: 6500
A43: 1042 | B43: 45724 | C43: West | D43: Office Chair | E43: Furniture | F43: 7 | G43: 6500
A44: 1043 | B44: 45728 | C44: North | D44: Backpack | E44: Accessories | F44: 4 | G44: 1500
... A91: 1090 | B91: 45812 | C91: West | D91: Backpack | E91: Accessories | F91: 9 | G91: 1500
A92: 1091 | B92: 45816 | C92: South | D92: Office Chair | E92: Furniture | G92: 6500
A93: 1092 | B93: 45818 | C93: West | D93: Backpack | E93: Accessories | F93: 10 | G93: 1500
A94: 1093 | B94: 45819 | C94: North | D94: Mobile | E94: Electronics | F94: 2 | G94: 18000
A95: 1094 | B95: 45821 | C95: East | D95: Mobile | E95: Electronics | F95: 3 | G95: 18000
A96: 1095 | B96: 45821 | C96: East | D96: Office Chair | E96: Furniture | F96: 6 | G96: 6500
A97: 1096 | B97: 45823 | C97: North | D97: Headphones | E97: Electronics | F97: 7 | G97: 2000
A98: 1097 | B98: 45824 | C98: West | D98: Office Chair | E98: Furniture | F98: 5 | G98: 6500
A99: 1098 | B99: 45824 | C99: North | D99: Notebook Pack | E99: Stationery | F99: 7 | G99: 250
A100: 1099 | B100: 45827 | C100: South | D100: Study Table | E100: Furniture | F100: 5 | G100: 5200
A101: 1100 | B101: 45831 | C101: East | D101: Pen Box | E101: Stationery | F101: 4 | G101: 120
A102: 1101 | B102: 45833 | C102: West | D102: Office Chair | E102: Furniture | F102: 3 | G102: 6500
A103: 1102 | B103: 45835 | C103: North | D103: Notebook Pack | E103: Stationery | F103: 8 | G103: 250
...
